[2022-07-28 10:03:13,296] {taskinstance.py:1159} INFO - Dependencies all met for <TaskInstance: user_processing.is_api_available manual__2022-07-28T10:03:11.396805+00:00 [queued]>
[2022-07-28 10:03:13,304] {taskinstance.py:1159} INFO - Dependencies all met for <TaskInstance: user_processing.is_api_available manual__2022-07-28T10:03:11.396805+00:00 [queued]>
[2022-07-28 10:03:13,305] {taskinstance.py:1356} INFO - 
--------------------------------------------------------------------------------
[2022-07-28 10:03:13,306] {taskinstance.py:1357} INFO - Starting attempt 1 of 1
[2022-07-28 10:03:13,306] {taskinstance.py:1358} INFO - 
--------------------------------------------------------------------------------
[2022-07-28 10:03:13,319] {taskinstance.py:1377} INFO - Executing <Task(HttpSensor): is_api_available> on 2022-07-28 10:03:11.396805+00:00
[2022-07-28 10:03:13,324] {standard_task_runner.py:52} INFO - Started process 413 to run task
[2022-07-28 10:03:13,327] {standard_task_runner.py:79} INFO - Running: ['***', 'tasks', 'run', 'user_processing', 'is_api_available', 'manual__2022-07-28T10:03:11.396805+00:00', '--job-id', '25', '--raw', '--subdir', 'DAGS_FOLDER/user_processing.py', '--cfg-path', '/tmp/tmp22yxtfq1', '--error-file', '/tmp/tmpuqzega64']
[2022-07-28 10:03:13,328] {standard_task_runner.py:80} INFO - Job 25: Subtask is_api_available
[2022-07-28 10:03:13,379] {task_command.py:369} INFO - Running <TaskInstance: user_processing.is_api_available manual__2022-07-28T10:03:11.396805+00:00 [running]> on host 890323d6f4a0
[2022-07-28 10:03:13,480] {taskinstance.py:1571} INFO - Exporting the following env vars:
AIRFLOW_CTX_DAG_OWNER=***
AIRFLOW_CTX_DAG_ID=user_processing
AIRFLOW_CTX_TASK_ID=is_api_available
AIRFLOW_CTX_EXECUTION_DATE=2022-07-28T10:03:11.396805+00:00
AIRFLOW_CTX_TRY_NUMBER=1
AIRFLOW_CTX_DAG_RUN_ID=manual__2022-07-28T10:03:11.396805+00:00
[2022-07-28 10:03:13,481] {http.py:97} INFO - Poking: api/
[2022-07-28 10:03:13,502] {taskinstance.py:1889} ERROR - Task failed with exception
Traceback (most recent call last):
  File "/home/airflow/.local/lib/python3.7/site-packages/airflow/sensors/base.py", line 277, in execute
    poke_return = self.poke(context)
  File "/home/airflow/.local/lib/python3.7/site-packages/airflow/providers/http/sensors/http.py", line 112, in poke
    raise exc
  File "/home/airflow/.local/lib/python3.7/site-packages/airflow/providers/http/sensors/http.py", line 103, in poke
    extra_options=self.extra_options,
  File "/home/airflow/.local/lib/python3.7/site-packages/airflow/providers/http/hooks/http.py", line 114, in run
    session = self.get_conn(headers)
  File "/home/airflow/.local/lib/python3.7/site-packages/airflow/providers/http/hooks/http.py", line 68, in get_conn
    conn = self.get_connection(self.http_conn_id)
  File "/home/airflow/.local/lib/python3.7/site-packages/airflow/hooks/base.py", line 67, in get_connection
    conn = Connection.get_connection_from_secrets(conn_id)
  File "/home/airflow/.local/lib/python3.7/site-packages/airflow/models/connection.py", line 430, in get_connection_from_secrets
    raise AirflowNotFoundException(f"The conn_id `{conn_id}` isn't defined")
airflow.exceptions.AirflowNotFoundException: The conn_id `user_api` isn't defined
[2022-07-28 10:03:13,506] {taskinstance.py:1400} INFO - Marking task as FAILED. dag_id=user_processing, task_id=is_api_available, execution_date=20220728T100311, start_date=20220728T100313, end_date=20220728T100313
[2022-07-28 10:03:13,517] {standard_task_runner.py:97} ERROR - Failed to execute job 25 for task is_api_available (The conn_id `user_api` isn't defined; 413)
[2022-07-28 10:03:13,540] {local_task_job.py:156} INFO - Task exited with return code 1
[2022-07-28 10:03:13,588] {local_task_job.py:273} INFO - 0 downstream tasks scheduled from follow-on schedule check
